<link name="left_wheel">
    <visual>
      <origin rpy="1.5708 0 0" xyz="0 0 0"/>
      <geometry><cylinder length="0.04" radius="0.035"/></geometry>
      <material name="black"><color rgba="0 0 0 1"/></material>
    </visual>
  </link>

  <joint name="left_wheel_joint" type="continuous">
    <parent link="base_link"/><child link="left_wheel"/>
    <origin xyz="-0.05 0.08 0" rpy="0 0 0"/>
    <axis xyz="0 1 0"/> </joint>

  <link name="right_wheel">
    <visual>
      <origin rpy="1.5708 0 0" xyz="0 0 0"/>
      <geometry><cylinder length="0.04" radius="0.035"/></geometry>
      <material name="black"><color rgba="0 0 0 1"/></material>
    </visual>
  </link>

  <joint name="right_wheel_joint" type="continuous">
    <parent link="base_link"/><child link="right_wheel"/>
    <origin xyz="-0.05 -0.08 0" rpy="0 0 0"/>
    <axis xyz="0 1 0"/>
  </joint>